Workbook

Sheet Dashboard
A1: DEEP DIVE BOTANICALS - FINANCIAL DASHBOARD
B4: KEY FINANCIAL METRICS (3-YEAR SUMMARY)
B5: Metric | C5: Year 1 | D5: Year 2 | E5: Year 3 | F5: 3-Yr Total
B6: Volume (cans) | C6: ='P&L Year 1 (Monthly)'!N5 | D6: ='P&L Years 2-3 (Quarterly)'!F5 | E6: ='P&L Years 2-3 (Quarterly)'!K5 | F6: =SUM(C6:E6)
B7: Revenue (€) | C7: ='P&L Year 1 (Monthly)'!N12 | D7: ='P&L Years 2-3 (Quarterly)'!F7 | E7: ='P&L Years 2-3 (Quarterly)'!K7 | F7: =SUM(C7:E7)
B8: Gross Margin % | C8: ='P&L Year 1 (Monthly)'!N21 | D8: ='P&L Years 2-3 (Quarterly)'!F13 | E8: ='P&L Years 2-3 (Quarterly)'!K13 | F8: =AVERAGE(C8:E8)
B9: EBITDA (€) | C9: ='P&L Year 1 (Monthly)'!N32 | D9: ='P&L Years 2-3 (Quarterly)'!F22 | E9: ='P&L Years 2-3 (Quarterly)'!K22 | F9: =SUM(C9:E9)
B10: EBITDA Margin % | C10: ='P&L Year 1 (Monthly)'!N33 | D10: ='P&L Years 2-3 (Quarterly)'!F23 | E10: ='P&L Years 2-3 (Quarterly)'!K23 | F10: =AVERAGE(C10:E10)
B11: Net Income (€) | C11: ='P&L Year 1 (Monthly)'!N40 | D11: ='P&L Years 2-3 (Quarterly)'!F30 | E11: ='P&L Years 2-3 (Quarterly)'!K30 | F11: =SUM(C11:E11)
B12: Cash Position (€) | C12: ='Cash Flow Statement'!N25 | D12: ='Base Case'!C20 | E12: ='Base Case'!D20 | F12: =E12
B15: SCENARIO COMPARISON (3-Year Cumulative)
B16: Metric | C16: Base Case | D16: Bull Case | E16: Bear Case
B17: Total Revenue | C17: ='Base Case'!E10 | D17: ='Bull Case'!E10 | E17: ='Bear Case'!E10
B18: Total EBITDA | C18: ='Base Case'!E17 | D18: ='Bull Case'!E17 | E18: ='Bear Case'!E17
B19: Final Cash Position | C19: ='Base Case'!E20 | D19: ='Bull Case'!E20 | E19: ='Bear Case'!E20
B22: UNIT ECONOMICS
B23: Metric | C23: Value
B24: Ex-Factory Price | C24: ='Unit Economics'!B5
B25: COGS per can | C25: ='Unit Economics'!B6
B26: Gross Profit per can | C26: ='Unit Economics'!B7
B27: Gross Margin % | C27: ='Unit Economics'!B8
B28: Contribution Margin I | C28: ='Unit Economics'!B11
B29: CM I % | C29: ='Unit Economics'!B12
B30: LTV / CAC Ratio | C30: ='Unit Economics'!B27
B31: Break-Even Volume | C31: ='Break-Even Analysis'!B27
B34: NOTE: Excel charts can be created manually using the chart tools. Recommended charts:
B35: • Revenue Growth: Line chart showing monthly/quarterly revenue across 3 years
B36: • Margin Evolution: Line chart with Gross Margin % and EBITDA Margin % over time
B37: • Cash Runway: Line chart showing cumulative cash position
B38: • Channel Mix: Pie chart showing revenue breakdown by channel
B39: • Scenario Comparison: Clustered bar chart comparing Base/Bull/Bear scenarios

Sheet Assumptions
A1: DEEP DIVE BOTANICALS - FINANCIAL ASSUMPTIONS
A3: Yellow cells are editable inputs. All other tabs reference these assumptions.
A5: 1. PRICING ASSUMPTIONS
A6: Parameter | B6: Value | C6: Unit | D6: Notes
A7: UVP (incl. MwSt) | B7: 1.74 | C7: € | D7: Consumer price (mid-point €1.69-1.79)
A8: MwSt Rate | B8: 0.19 | D8: 19% German VAT
A9: Pfand | B9: 0.25 | C9: € | D9: Separate deposit
A10: Retailer Margin | B10: 0.4 | C10: % | D10: As % of UVP (35-45% range)
A11: Distributor Margin | B11: 0.2 | C11: % | D11: As % of remaining (15-25% range)
A12: Ex-Factory Price (calculated) | B12: =B7/(1+B8)/(1-B10)/(1-B11) | C12: € | D12: Automated calculation
A14: 2. COGS BREAKDOWN (per can)
A15: Component | B15: Cost (€) | C15: Range | D15: Notes
A16: Aroma/Distillates | B16: 0.0475 | C16: €0.035-0.060 | D16: Botanical extracts, essential oils
A17: Acids/Sweetener/Minerals | B17: 0.015 | C17: €0.010-0.020 | D17: Citric acid, natural sweeteners, minerals
A18: Water/CO2 | B18: 0.0075 | C18: €0.005-0.010 | D18: Purified water, carbonation
A19: Can Body (250ml) | B19: 0.145 | C19: €0.130-0.160 | D19: Aluminum can - largest cost component
A20: End/Tab | B20: 0.025 | C20: €0.020-0.030 | D20: Can lid and tab
A21: Co-Packing/Filling | B21: 0.1 | C21: €0.080-0.120 | D21: Contract manufacturing/filling
A22: Secondary Packaging | B22: 0.06 | C22: €0.050-0.070 | D22: Cardboard trays, shrink wrap
A23: Logistics/Freight | B23: 0.04 | C23: €0.030-0.050 | D23: Transport to warehouse
A24: QC/Testing | B24: 0.0075 | C24: €0.005-0.010 | D24: Quality control, lab tests
A25: Total COGS (calculated) | B25: =SUM(B16:B24) | C25: €0.40 target | D25: Sum of all components
A27: 3. VOLUME ASSUMPTIONS
A28: Parameter | B28: Value | C28: Unit | D28: Notes
A29: Year 1 Total Volume | B29: 100000 | C29: cans | D29: Conservative first year target
A30: Year 2 Total Volume | B30: 275000 | C30: cans | D30: 175% growth
A31: Year 3 Total Volume | B31: 475000 | C31: cans | D31: 73% growth
A32: Summer Seasonality Factor | B32: 0.15 | C32: % | D32: +15% in Jun-Aug
A33: Winter Seasonality Factor | B33: -0.1 | C33: % | D33: -10% in Dec-Feb
A34: Number of SKUs | B34: 2 | D34: Citrus Juniper, Ginger Bergamot
A36: 4. CHANNEL MIX (% of volume)
A37: Channel | B37: Year 1 | C37: Year 2 | D37: Year 3
A38: LEH (Retail) | B38: 0.45 | C38: 0.5 | D38: 0.55
A39: Office/B2B | B39: 0.25 | C39: 0.25 | D39: 0.25
A40: Gastro/HoReCa | B40: 0.2 | C40: 0.15 | D40: 0.12
A41: DTC (Direct) | B41: 0.1 | C41: 0.1 | D41: 0.08
A42: Total (must = 100%) | B42: =SUM(B38:B41) | C42: =SUM(C38:C41) | D42: =SUM(D38:D41)
A44: 5. PERSONNEL COSTS
A45: Role | B45: Annual Cost (€) | C45: FTE | D45: Notes
A46: Founder (pre-funding) | B46: 0 | C46: 1 | D46: Deferred until funding received
...

Sheet P&L Year 1 (Monthly)
A1: DEEP DIVE BOTANICALS - YEAR 1 PROFIT & LOSS (MONTHLY)
A3: Line Item | B3: Jan | C3: Feb | D3: Mar | E3: Apr | F3: May | G3: Jun | H3: Jul | I3: Aug | J3: Sep | K3: Oct | L3: Nov | M3: Dec | N3: Year 1 Total
A4: REVENUE
A5: Units Sold | B5: =Assumptions!$B$38/12*0.9 | C5: =Assumptions!$B$38/12*0.9 | D5: =Assumptions!$B$38/12*1.0 | E5: =Assumptions!$B$38/12*1.0 | F5: =Assumptions!$B$38/12*1.0 | G5: =Assumptions!$B$38/12*1.15 | H5: =Assumptions!$B$38/12*1.15 | I5: =Assumptions!$B$38/12*1.15 | J5: =Assumptions!$B$38/12*1.0 | K5: =Assumptions!$B$38/12*1.0 | L5: =Assumptions!$B$38/12*1.0 | M5: =Assumptions!$B$38/12*0.9 | N5: =SUM(B5:M5)
A6: LEH (Retail) | B6: =B5*Assumptions!$B$47 | C6: =B5*Assumptions!$B$47 | D6: =B5*Assumptions!$B$47 | E6: =B5*Assumptions!$B$47 | F6: =B5*Assumptions!$B$47 | G6: =B5*Assumptions!$B$47 | H6: =B5*Assumptions!$B$47 | I6: =B5*Assumptions!$B$47 | J6: =B5*Assumptions!$B$47 | K6: =B5*Assumptions!$B$47 | L6: =B5*Assumptions!$B$47 | M6: =B5*Assumptions!$B$47 | N6: =SUM(B6:M6)
A7: Office/B2B | B7: =B5*Assumptions!$B$48 | C7: =B5*Assumptions!$B$48 | D7: =B5*Assumptions!$B$48 | E7: =B5*Assumptions!$B$48 | F7: =B5*Assumptions!$B$48 | G7: =B5*Assumptions!$B$48 | H7: =B5*Assumptions!$B$48 | I7: =B5*Assumptions!$B$48 | J7: =B5*Assumptions!$B$48 | K7: =B5*Assumptions!$B$48 | L7: =B5*Assumptions!$B$48 | M7: =B5*Assumptions!$B$48 | N7: =SUM(B7:M7)
A8: Gastro/HoReCa | B8: =B5*Assumptions!$B$49 | C8: =B5*Assumptions!$B$49 | D8: =B5*Assumptions!$B$49 | E8: =B5*Assumptions!$B$49 | F8: =B5*Assumptions!$B$49 | G8: =B5*Assumptions!$B$49 | H8: =B5*Assumptions!$B$49 | I8: =B5*Assumptions!$B$49 | J8: =B5*Assumptions!$B$49 | K8: =B5*Assumptions!$B$49 | L8: =B5*Assumptions!$B$49 | M8: =B5*Assumptions!$B$49 | N8: =SUM(B8:M8)
A9: DTC (Direct) | B9: =B5*Assumptions!$B$50 | C9: =B5*Assumptions!$B$50 | D9: =B5*Assumptions!$B$50 | E9: =B5*Assumptions!$B$50 | F9: =B5*Assumptions!$B$50 | G9: =B5*Assumptions!$B$50 | H9: =B5*Assumptions!$B$50 | I9: =B5*Assumptions!$B$50 | J9: =B5*Assumptions!$B$50 | K9: =B5*Assumptions!$B$50 | L9: =B5*Assumptions!$B$50 | M9: =B5*Assumptions!$B$50 | N9: =SUM(B9:M9)
A11: Revenue (ex-factory) | B11: =B5*Assumptions!$B$12 | C11: =B5*Assumptions!$B$12 | D11: =B5*Assumptions!$B$12 | E11: =B5*Assumptions!$B$12 | F11: =B5*Assumptions!$B$12 | G11: =B5*Assumptions!$B$12 | H11: =B5*Assumptions!$B$12 | I11: =B5*Assumptions!$B$12 | J11: =B5*Assumptions!$B$12 | K11: =B5*Assumptions!$B$12 | L11: =B5*Assumptions!$B$12 | M11: =B5*Assumptions!$B$12 | N11: =SUM(B11:M11)
A12: LEH Revenue | B12: =B6*Assumptions!$B$12 | C12: =B6*Assumptions!$B$12 | D12: =B6*Assumptions!$B$12 | E12: =B6*Assumptions!$B$12 | F12: =B6*Assumptions!$B$12 | G12: =B6*Assumptions!$B$12 | H12: =B6*Assumptions!$B$12 | I12: =B6*Assumptions!$B$12 | J12: =B6*Assumptions!$B$12 | K12: =B6*Assumptions!$B$12 | L12: =B6*Assumptions!$B$12 | M12: =B6*Assumptions!$B$12 | N12: =SUM(B12:M12)
A13: Office Revenue | B13: =B7*Assumptions!$B$12 | C13: =B7*Assumptions!$B$12 | D13: =B7*Assumptions!$B$12 | E13: =B7*Assumptions!$B$12 | F13: =B7*Assumptions!$B$12 | G13: =B7*Assumptions!$B$12 | H13: =B7*Assumptions!$B$12 | I13: =B7*Assumptions!$B$12 | J13: =B7*Assumptions!$B$12 | K13: =B7*Assumptions!$B$12 | L13: =B7*Assumptions!$B$12 | M13: =B7*Assumptions!$B$12 | N13: =SUM(B13:M13)
A14: Gastro Revenue | B14: =B8*Assumptions!$B$12 | C14: =B8*Assumptions!$B$12 | D14: =B8*Assumptions!$B$12 | E14: =B8*Assumptions!$B$12 | F14: =B8*Assumptions!$B$12 | G14: =B8*Assumptions!$B$12 | H14: =B8*Assumptions!$B$12 | I14: =B8*Assumptions!$B$12 | J14: =B8*Assumptions!$B$12 | K14: =B8*Assumptions!$B$12 | L14: =B8*Assumptions!$B$12 | M14: =B8*Assumptions!$B$12 | N14: =SUM(B14:M14)
A15: DTC Revenue | B15: =B9*Assumptions!$B$12 | C15: =B9*Assumptions!$B$12 | D15: =B9*Assumptions!$B$12 | E15: =B9*Assumptions!$B$12 | F15: =B9*Assumptions!$B$12 | G15: =B9*Assumptions!$B$12 | H15: =B9*Assumptions!$B$12 | I15: =B9*Assumptions!$B$12 | J15: =B9*Assumptions!$B$12 | K15: =B9*Assumptions!$B$12 | L15: =B9*Assumptions!$B$12 | M15: =B9*Assumptions!$B$12 | N15: =SUM(B15:M15)
A17: COST OF GOODS SOLD
A18: COGS per unit | B18: =Assumptions!$B$27 | C18: =Assumptions!$B$27 | D18: =Assumptions!$B$27 | E18: =Assumptions!$B$27 | F18: =Assumptions!$B$27 | G18: =Assumptions!$B$27 | H18: =Assumptions!$B$27 | I18: =Assumptions!$B$27 | ... N18: =Assumptions!$B$27
A19: Total COGS | B19: =B5*B18 | C19: =B5*B18 | D19: =B5*B18 | E19: =B5*B18 | F19: =B5*B18 | G19: =B5*B18 | H19: =B5*B18 | I19: =B5*B18 | J19: =B5*B18 | K19: =B5*B18 | L19: =B5*B18 | M19: =B5*B18 | N19: =SUM(B19:M19)
A20: Gross Profit | B20: =B12-B19 | C20: =B12-B19 | D20: =B12-B19 | E20: =B12-B19 | F20: =B12-B19 | G20: =B12-B19 | H20: =B12-B19 | I20: =B12-B19 | J20: =B12-B19 | K20: =B12-B19 | L20: =B12-B19 | M20: =B12-B19 | N20: =SUM(B20:M20)
A21: Gross Margin % | B21: =B20/B12 | C21: =B20/B12 | D21: =B20/B12 | E21: =B20/B12 | F21: =B20/B12 | G21: =B20/B12 | H21: =B20/B12 | I21: =B20/B12 | J21: =B20/B12 | K21: =B20/B12 | L21: =B20/B12 | M21: =B20/B12 | N21: =N20/N12
A23: OPERATING EXPENSES
A24: Personnel Costs | B24: =(Assumptions!$B$59+Assumptions!$B$60+Assumptions!$B$61)*(1+Assumptions!$B$62)/12 | C24: =(Assumptions!$B$59+Assumptions!$B$60+Assumptions!$B$61)*(1+Assumptions!$B$62)/12 | D24: =(Assumptions!$B$59+Assumptions!$B$60+Assumptions!$B$61)*(1+Assumptions!$B$62)/12 | E24: =(Assumptions!$B$59+Assumptions!$B$60+Assumptions!$B$61)*(1+Assumptions!$B$62)/12 | F24: =(Assumptions!$B$59+Assumptions!$B$60+Assumptions!$B$61)*(1+Assumptions!$B$62)/12 | G24: =(Assumptions!$B$59+Assumptions!$B$60+Assumptions!$B$61)*(1+Assumptions!$B$62)/12 | H24: =(Assumptions!$B$59+Assumptions!$B$60+Assumptions!$B$61)*(1+Assumptions!$B$62)/12 | I24: =(Assumptions!$B$59+Assumptions!$B$60+Assumptions!$B$61)*(1+Assumptions!$B$62)/12 | ... M24: =(Assumptions!$B$59+Assumptions!$B$60+Assumptions!$B$61)*(1+Assumptions!$B$62)/12 | N24: =SUM(B24:M24)
A25: Marketing & Trade | B25: =B12*Assumptions!$B$66 | C25: =B12*Assumptions!$B$66 | D25: =B12*Assumptions!$B$66 | E25: =B12*Assumptions!$B$66 | F25: =B12*Assumptions!$B$66 | G25: =B12*Assumptions!$B$66 | H25: =B12*Assumptions!$B$66 | I25: =B12*Assumptions!$B$66 | J25: =B12*Assumptions!$B$66 | K25: =B12*Assumptions!$B$66 | L25: =B12*Assumptions!$B$66 | M25: =B12*Assumptions!$B$66 | N25: =SUM(B25:M25)
A26: G&A | B26: =Assumptions!$B$67 | C26: =Assumptions!$B$67 | D26: =Assumptions!$B$67 | E26: =Assumptions!$B$67 | F26: =Assumptions!$B$67 | G26: =Assumptions!$B$67 | H26: =Assumptions!$B$67 | I26: =Assumptions!$B$67 | ... M26: =Assumptions!$B$67 | N26: =SUM(B26:M26)
A27: Quality/Lab Testing | B27: =Assumptions!$B$68/12 | C27: =Assumptions!$B$68/12 | D27: =Assumptions!$B$68/12 | E27: =Assumptions!$B$68/12 | F27: =Assumptions!$B$68/12 | G27: =Assumptions!$B$68/12 | H27: =Assumptions!$B$68/12 | I27: =Assumptions!$B$68/12 | ... M27: =Assumptions!$B$68/12 | N27: =SUM(B27:M27)
A28: Design/Labels (one-time) | B28: =Assumptions!$B$69 | C28: 0 | D28: 0 | E28: 0 | F28: 0 | G28: 0 | H28: 0 | I28: 0 | J28: 0 | K28: 0 | L28: 0 | M28: 0 | N28: =SUM(B28:M28)
A29: Insurance | B29: =Assumptions!$B$70/12 | C29: =Assumptions!$B$70/12 | D29: =Assumptions!$B$70/12 | E29: =Assumptions!$B$70/12 | F29: =Assumptions!$B$70/12 | G29: =Assumptions!$B$70/12 | H29: =Assumptions!$B$70/12 | I29: =Assumptions!$B$70/12 | ... M29: =Assumptions!$B$70/12 | N29: =SUM(B29:M29)
A30: Legal/Accounting | B30: =Assumptions!$B$71/12 | C30: =Assumptions!$B$71/12 | D30: =Assumptions!$B$71/12 | E30: =Assumptions!$B$71/12 | F30: =Assumptions!$B$71/12 | G30: =Assumptions!$B$71/12 | H30: =Assumptions!$B$71/12 | I30: =Assumptions!$B$71/12 | ... M30: =Assumptions!$B$71/12 | N30: =SUM(B30:M30)
A31: Total OpEx | B31: =SUM(B24:B30) | C31: =SUM(B24:B30) | D31: =SUM(B24:B30) | E31: =SUM(B24:B30) | F31: =SUM(B24:B30) | G31: =SUM(B24:B30) | H31: =SUM(B24:B30) | I31: =SUM(B24:B30) | J31: =SUM(B24:B30) | K31: =SUM(B24:B30) | L31: =SUM(B24:B30) | M31: =SUM(B24:B30) | N31: =SUM(B31:M31)
A33: EBITDA | B33: =B20-B23 | C33: =B20-B23 | D33: =B20-B23 | E33: =B20-B23 | F33: =B20-B23 | G33: =B20-B23 | H33: =B20-B23 | I33: =B20-B23 | J33: =B20-B23 | K33: =B20-B23 | L33: =B20-B23 | M33: =B20-B23 | N33: =SUM(B33:M33)
A34: EBITDA Margin % | B34: =B33/B12 | C34: =B33/B12 | D34: =B33/B12 | E34: =B33/B12 | F34: =B33/B12 | G34: =B33/B12 | H34: =B33/B12 | I34: =B33/B12 | J34: =B33/B12 | K34: =B33/B12 | L34: =B33/B12 | M34: =B33/B12 | N34: =N33/N12
A36: Depreciation & Amortization | B36: 0 | C36: 0 | D36: 0 | E36: 0 | F36: 0 | G36: 0 | H36: 0 | I36: 0 | J36: 0 | K36: 0 | L36: 0 | M36: 0 | N36: =SUM(B36:M36)
A37: EBIT | B37: =B34-B36 | C37: =B34-B36 | D37: =B34-B36 | E37: =B34-B36 | F37: =B34-B36 | G37: =B34-B36 | H37: =B34-B36 | I37: =B34-B36 | J37: =B34-B36 | K37: =B34-B36 | L37: =B34-B36 | M37: =B34-B36 | N37: =SUM(B37:M37)
A38: Interest Expense | B38: =Assumptions!$B$83*Assumptions!$B$82/12 | C38: =Assumptions!$B$83*Assumptions!$B$82/12 | D38: =Assumptions!$B$83*Assumptions!$B$82/12 | E38: =Assumptions!$B$83*Assumptions!$B$82/12 | F38: =Assumptions!$B$83*Assumptions!$B$82/12 | G38: =Assumptions!$B$83*Assumptions!$B$82/12 | H38: =Assumptions!$B$83*Assumptions!$B$82/12 | I38: =Assumptions!$B$83*Assumptions!$B$82/12 | ... M38: =Assumptions!$B$83*Assumptions!$B$82/12 | N38: =SUM(B38:M38)
A39: EBT | B39: =B37-B38 | C39: =B37-B38 | D39: =B37-B38 | E39: =B37-B38 | F39: =B37-B38 | G39: =B37-B38 | H39: =B37-B38 | I39: =B37-B38 | J39: =B37-B38 | K39: =B37-B38 | L39: =B37-B38 | M39: =B37-B38 | N39: =SUM(B39:M39)
A40: Taxes | B40: =IF(B39>0,B39*Assumptions!$B$87,0) | C40: =IF(B39>0,B39*Assumptions!$B$87,0) | D40: =IF(B39>0,B39*Assumptions!$B$87,0) | E40: =IF(B39>0,B39*Assumptions!$B$87,0) | F40: =IF(B39>0,B39*Assumptions!$B$87,0) | G40: =IF(B39>0,B39*Assumptions!$B$87,0) | H40: =IF(B39>0,B39*Assumptions!$B$87,0) | I40: =IF(B39>0,B39*Assumptions!$B$87,0) | J40: =IF(B39>0,B39*Assumptions!$B$87,0) | K40: =IF(B39>0,B39*Assumptions!$B$87,0) | L40: =IF(B39>0,B39*Assumptions!$B$87,0) | M40: =IF(B39>0,B39*Assumptions!$B$87,0) | N40: =SUM(B40:M40)
A41: NET INCOME | B41: =B39-B40 | C41: =B39-B40 | D41: =B39-B40 | E41: =B39-B40 | F41: =B39-B40 | G41: =B39-B40 | H41: =B39-B40 | I41: =B39-B40 | J41: =B39-B40 | K41: =B39-B40 | L41: =B39-B40 | M41: =B39-B40 | N41: =SUM(B41:M41)
A42: Net Margin % | B42: =B41/B12 | C42: =B41/B12 | D42: =B41/B12 | E42: =B41/B12 | F42: =B41/B12 | G42: =B41/B12 | H42: =B41/B12 | I42: =B41/B12 | J42: =B41/B12 | K42: =B41/B12 | L42: =B41/B12 | M42: =B41/B12 | N42: =N41/N12

Sheet P&L Years 2-3 (Quarterly)
A1: DEEP DIVE BOTANICALS - YEARS 2-3 PROFIT & LOSS (QUARTERLY)
A3: Line Item | B3: Y2 Q1 | C3: Y2 Q2 | D3: Y2 Q3 | E3: Y2 Q4 | F3: Y2 Total | G3: Y3 Q1 | H3: Y3 Q2 | I3: Y3 Q3 | J3: Y3 Q4 | K3: Y3 Total
A4: REVENUE
A5: Units Sold | B5: =Assumptions!$B$39/4 | C5: =Assumptions!$B$39/4 | D5: =Assumptions!$B$39/4 | E5: =Assumptions!$B$39/4 | F5: =SUM(B5:E5) | G5: =Assumptions!$B$40/4 | H5: =Assumptions!$B$40/4 | I5: =Assumptions!$B$40/4 | J5: =Assumptions!$B$40/4 | K5: =SUM(G5:J5)
A6: Revenue (ex-factory) | B6: =B5*Assumptions!$B$12 | C6: =B5*Assumptions!$B$12 | D6: =B5*Assumptions!$B$12 | E6: =B5*Assumptions!$B$12 | F6: =SUM(B6:E6) | G6: =G5*Assumptions!$B$12 | H6: =G5*Assumptions!$B$12 | I6: =G5*Assumptions!$B$12 | J6: =G5*Assumptions!$B$12 | K6: =SUM(G6:J6)
A8: COST OF GOODS SOLD
A9: COGS per unit | B9: =Assumptions!$B$27 | C9: =Assumptions!$B$27 | D9: =Assumptions!$B$27 | E9: =Assumptions!$B$27 | F9: =SUM(B9:E9) | G9: =Assumptions!$B$27 | H9: =Assumptions!$B$27 | I9: =Assumptions!$B$27 | J9: =Assumptions!$B$27 | K9: =SUM(G9:J9)
A10: Total COGS | B10: =B8*B9 | C10: =B8*B9 | D10: =B8*B9 | E10: =B8*B9 | F10: =SUM(B10:E10) | G10: =G8*G9 | H10: =G8*G9 | I10: =G8*G9 | J10: =G8*G9 | K10: =SUM(G10:J10)
A11: Gross Profit | B11: =B7-B10 | C11: =B7-B10 | D11: =B7-B10 | E11: =B7-B10 | F11: =SUM(B11:E11) | G11: =G7-G10 | H11: =G7-G10 | I11: =G7-G10 | J11: =G7-G10 | K11: =SUM(G11:J11)
A12: Gross Margin % | B12: =B11/B8 | C12: =B11/B8 | D12: =B11/B8 | E12: =B11/B8 | F12: =SUM(B12:E12) | G12: =G11/G8 | H12: =G11/G8 | I12: =G11/G8 | J12: =G11/G8 | K12: =SUM(G12:J12)
A14: OPERATING EXPENSES
A15: Personnel Costs | B15: =(Assumptions!$B$59+Assumptions!$B$60+Assumptions!$B$61)*(1+Assumptions!$B$62)/4 | C15: =(Assumptions!$B$59+Assumptions!$B$60+Assumptions!$B$61)*(1+Assumptions!$B$62)/4 | D15: =(Assumptions!$B$59+Assumptions!$B$60+Assumptions!$B$61)*(1+Assumptions!$B$62)/4 | E15: =(Assumptions!$B$59+Assumptions!$B$60+Assumptions!$B$61)*(1+Assumptions!$B$62)/4 | F15: =SUM(B15:E15) | G15: =(Assumptions!$B$59+Assumptions!$B$60+Assumptions!$B$61)*(1+Assumptions!$B$62)/4 | H15: =(Assumptions!$B$59+Assumptions!$B$60+Assumptions!$B$61)*(1+Assumptions!$B$62)/4 | I15: =(Assumptions!$B$59+Assumptions!$B$60+Assumptions!$B$61)*(1+Assumptions!$B$62)/4 | J15: =(Assumptions!$B$59+Assumptions!$B$60+Assumptions!$B$61)*(1+Assumptions!$B$62)/4 | K15: =SUM(G15:J15)
A16: Marketing & Trade | B16: =B6*Assumptions!$B$66 | C16: =B6*Assumptions!$B$66 | D16: =B6*Assumptions!$B$66 | E16: =B6*Assumptions!$B$66 | F16: =SUM(B16:E16) | G16: =G6*Assumptions!$B$66 | H16: =G6*Assumptions!$B$66 | I16: =G6*Assumptions!$B$66 | J16: =G6*Assumptions!$B$66 | K16: =SUM(G16:J16)
A17: G&A | B17: =Assumptions!$B$67*3 | C17: =Assumptions!$B$67*3 | D17: =Assumptions!$B$67*3 | E17: =Assumptions!$B$67*3 | F17: =SUM(B17:E17) | G17: =Assumptions!$B$67*3 | H17: =Assumptions!$B$67*3 | I17: =Assumptions!$B$67*3 | J17: =Assumptions!$B$67*3 | K17: =SUM(G17:J17)
A18: Other OpEx | B18: =(Assumptions!$B$68+Assumptions!$B$70+Assumptions!$B$71)/4 | C18: =(Assumptions!$B$68+Assumptions!$B$70+Assumptions!$B$71)/4 | D18: =(Assumptions!$B$68+Assumptions!$B$70+Assumptions!$B$71)/4 | E18: =(Assumptions!$B$68+Assumptions!$B$70+Assumptions!$B$71)/4 | F18: =SUM(B18:E18) | G18: =(Assumptions!$B$68+Assumptions!$B$70+Assumptions!$B$71)/4 | H18: =(Assumptions!$B$68+Assumptions!$B$70+Assumptions!$B$71)/4 | I18: =(Assumptions!$B$68+Assumptions!$B$70+Assumptions!$B$71)/4 | J18: =(Assumptions!$B$68+Assumptions!$B$70+Assumptions!$B$71)/4 | K18: =SUM(G18:J18)
A19: Total OpEx | B19: =SUM(B15:B18) | C19: =SUM(B15:B18) | D19: =SUM(B15:B18) | E19: =SUM(B15:B18) | F19: =SUM(B19:E19) | G19: =SUM(G15:G18) | H19: =SUM(G15:G18) | I19: =SUM(G15:G18) | J19: =SUM(G15:G18) | K19: =SUM(G19:J19)
A21: EBITDA | B21: =B10-B20 | C21: =B10-B20 | D21: =B10-B20 | E21: =B10-B20 | F21: =SUM(B21:E21) | G21: =G10-G20 | H21: =G10-G20 | I21: =G10-G20 | J21: =G10-G20 | K21: =SUM(G21:J21)
A22: EBITDA Margin % | B22: =B21/B9 | C22: =B21/B9 | D22: =B21/B9 | E22: =B21/B9 | F22: =SUM(B22:E22) | G22: =G21/G9 | H22: =G21/G9 | I22: =G21/G9 | J22: =G21/G9 | K22: =SUM(G22:J22)
A24: Depreciation & Amortization | B24: 500 | C24: 500 | D24: 500 | E24: 500 | F24: =SUM(B24:E24) | G24: 500 | H24: 500 | I24: 500 | J24: 500 | K24: =SUM(G24:J24)
A25: EBIT | B25: =B22-B24 | C25: =B22-B24 | D25: =B22-B24 | E25: =B22-B24 | F25: =SUM(B25:E25) | G25: =G22-G24 | H25: =G22-G24 | I25: =G22-G24 | J25: =G22-G24 | K25: =SUM(G25:J25)
A26: Interest Expense | B26: =Assumptions!$B$83*Assumptions!$B$82/4 | C26: =Assumptions!$B$83*Assumptions!$B$82/4 | D26: =Assumptions!$B$83*Assumptions!$B$82/4 | E26: =Assumptions!$B$83*Assumptions!$B$82/4 | F26: =SUM(B26:E26) | G26: =Assumptions!$B$83*Assumptions!$B$82/4 | H26: =Assumptions!$B$83*Assumptions!$B$82/4 | I26: =Assumptions!$B$83*Assumptions!$B$82/4 | J26: =Assumptions!$B$83*Assumptions!$B$82/4 | K26: =SUM(G26:J26)
A27: EBT | B27: =B25-B26 | C27: =B25-B26 | D27: =B25-B26 | E27: =B25-B26 | F27: =SUM(B27:E27) | G27: =G25-G26 | H27: =G25-G26 | I27: =G25-G26 | J27: =G25-G26 | K27: =SUM(G27:J27)
A28: Taxes | B28: =IF(B27>0,B27*Assumptions!$B$87,0) | C28: =IF(B27>0,B27*Assumptions!$B$87,0) | D28: =IF(B27>0,B27*Assumptions!$B$87,0) | E28: =IF(B27>0,B27*Assumptions!$B$87,0) | F28: =SUM(B28:E28) | G28: =IF(G27>0,G27*Assumptions!$B$87,0) | H28: =IF(G27>0,G27*Assumptions!$B$87,0) | I28: =IF(G27>0,G27*Assumptions!$B$87,0) | J28: =IF(G27>0,G27*Assumptions!$B$87,0) | K28: =SUM(G28:J28)
A29: NET INCOME | B29: =B27-B28 | C29: =B27-B28 | D29: =B27-B28 | E29: =B27-B28 | F29: =SUM(B29:E29) | G29: =G27-G28 | H29: =G27-G28 | I29: =G27-G28 | J29: =G27-G28 | K29: =SUM(G29:J29)
A30: Net Margin % | B30: =B29/B6 | C30: =B29/B6 | D30: =B29/B6 | E30: =B29/B6 | F30: =SUM(B30:E30) | G30: =G29/G6 | H30: =G29/G6 | I30: =G29/G6 | J30: =G29/G6 | K30: =SUM(G30:J30)

Sheet Cash Flow Statement
A1: DEEP DIVE BOTANICALS - CASH FLOW STATEMENT
A3: Cash Flow Item | B3: Jan | C3: Feb | D3: Mar | E3: Apr | F3: May | G3: Jun | H3: Jul | I3: Aug | J3: Sep | K3: Oct | L3: Nov | M3: Dec | N3: Year 1 Total
A4: OPERATING ACTIVITIES
A5: Net Income | B5: ='P&L Year 1 (Monthly)'!B39 | C5: ='P&L Year 1 (Monthly)'!C39 | D5: ='P&L Year 1 (Monthly)'!D39 | E5: ='P&L Year 1 (Monthly)'!E39 | F5: ='P&L Year 1 (Monthly)'!F39 | G5: ='P&L Year 1 (Monthly)'!G39 | H5: ='P&L Year 1 (Monthly)'!H39 | I5: ='P&L Year 1 (Monthly)'!I39 | ... M5: ='P&L Year 1 (Monthly)'!M39 | N5: =SUM(B5:M5)
A6: Add: Depreciation & Amortization | B6: ='P&L Year 1 (Monthly)'!B33 | C6: ='P&L Year 1 (Monthly)'!C33 | D6: ='P&L Year 1 (Monthly)'!D33 | E6: ='P&L Year 1 (Monthly)'!E33 | F6: ='P&L Year 1 (Monthly)'!F33 | G6: ='P&L Year 1 (Monthly)'!G33 | H6: ='P&L Year 1 (Monthly)'!H33 | I6: ='P&L Year 1 (Monthly)'!I33 | ... M6: ='P&L Year 1 (Monthly)'!M33 | N6: =SUM(B6:M6)
A7: Changes in Working Capital:
A8: Accounts Receivable | B8: =-('P&L Year 1 (Monthly)'!B12*45/30) | C8: =-('P&L Year 1 (Monthly)'!C12*45/30) | D8: =-('P&L Year 1 (Monthly)'!D12*45/30) | E8: =-('P&L Year 1 (Monthly)'!E12*45/30) | F8: =-('P&L Year 1 (Monthly)'!F12*45/30) | G8: =-('P&L Year 1 (Monthly)'!G12*45/30) | H8: =-('P&L Year 1 (Monthly)'!H12*45/30) | I8: =-('P&L Year 1 (Monthly)'!I12*45/30) | ... M8: =-('P&L Year 1 (Monthly)'!M12*45/30) | N8: =SUM(B8:M8)
A9: Inventory | B9: =-('P&L Year 1 (Monthly)'!B18*30/30) | C9: =-('P&L Year 1 (Monthly)'!C18*30/30) | D9: =-('P&L Year 1 (Monthly)'!D18*30/30) | E9: =-('P&L Year 1 (Monthly)'!E18*30/30) | F9: =-('P&L Year 1 (Monthly)'!F18*30/30) | G9: =-('P&L Year 1 (Monthly)'!G18*30/30) | H9: =-('P&L Year 1 (Monthly)'!H18*30/30) | I9: =-('P&L Year 1 (Monthly)'!I18*30/30) | ... M9: =-('P&L Year 1 (Monthly)'!M18*30/30) | N9: =SUM(B9:M9)
A10: Accounts Payable | B10: =('P&L Year 1 (Monthly)'!B18*30/30) | C10: =('P&L Year 1 (Monthly)'!C18*30/30) | D10: =('P&L Year 1 (Monthly)'!D18*30/30) | E10: =('P&L Year 1 (Monthly)'!E18*30/30) | F10: =('P&L Year 1 (Monthly)'!F18*30/30) | G10: =('P&L Year 1 (Monthly)'!G18*30/30) | H10: =('P&L Year 1 (Monthly)'!H18*30/30) | I10: =('P&L Year 1 (Monthly)'!I18*30/30) | ... M10: =('P&L Year 1 (Monthly)'!M18*30/30) | N10: =SUM(B10:M10)
A11: Cash from Operations | B11: =SUM(B5:B10) | C11: =SUM(C5:C10) | D11: =SUM(D5:D10) | E11: =SUM(E5:E10) | F11: =SUM(F5:F10) | G11: =SUM(G5:G10) | H11: =SUM(H5:H10) | I11: =SUM(I5:I10) | ... M11: =SUM(M5:M10) | N11: =SUM(B11:M11)
A13: INVESTING ACTIVITIES
A14: CapEx | B14: -1000 | C14: 0 | D14: 0 | E14: 0 | F14: 0 | G14: 0 | H14: 0 | I14: 0 | J14: 0 | K14: 0 | L14: 0 | M14: 0 | N14: =SUM(B14:M14)
A15: Cash from Investing | B15: =B14 | C15: =C14 | D15: =D14 | E15: =E14 | F15: =F14 | G15: =G14 | H15: =H14 | I15: =I14 | ... M15: =M14 | N15: =SUM(B15:M15)
A17: FINANCING ACTIVITIES
A18: Equity/Loan Proceeds | B18: =Assumptions!$B$81+Assumptions!$B$82 | C18: 0 | D18: 0 | E18: 0 | F18: 0 | G18: 0 | H18: 0 | I18: 0 | J18: 0 | K18: 0 | L18: 0 | M18: 0 | N18: =SUM(B18:M18)
A19: Loan Repayments | B19: 0 | C19: 0 | D19: 0 | E19: 0 | F19: 0 | G19: 0 | H19: 0 | I19: 0 | J19: 0 | K19: 0 | L19: 0 | M19: 0 | N19: =SUM(B19:M19)
A20: Cash from Financing | B20: =B18+B19 | C20: =C18+C19 | D20: =D18+D19 | E20: =E18+E19 | F20: =F18+F19 | G20: =G18+G19 | H20: =H18+H19 | I20: =I18+I19 | ... M20: =M18+M19 | N20: =SUM(B20:M20)
A22: NET CHANGE IN CASH | B22: =B18+B20+B21 | C22: =C18+C20+C21 | D22: =D18+D20+D21 | E22: =E18+E20+E21 | F22: =F18+F20+F21 | G22: =G18+G20+G21 | H22: =H18+H20+H21 | I22: =I18+I20+I21 | ... M22: =M18+M20+M21 | N22: =SUM(B22:M22)
A23: Beginning Cash Balance | B23: 0 | C23: =B24 | D23: =C24 | E23: =D24 | F23: =E24 | G23: =F24 | H23: =G24 | I23: =H24 | J23: =I24 | ... M23: =L24 | N23: =B23
A24: Ending Cash Balance | B24: =B22+B23 | C24: =C22+C23 | D24: =D22+D23 | E24: =E22+E23 | F24: =F22+F23 | G24: =G22+G23 | H24: =H22+H23 | I24: =I22+I23 | ... M24: =M22+M23 | N24: =M24

Sheet Unit Economics
A1: DEEP DIVE BOTANICALS - UNIT ECONOMICS
A3: PER-CAN ECONOMICS | C3: TRUE
A4: Selling Price (ex-factory) | B4: =Assumptions!$B$12 | C4: €
A5: COGS per can | B5: =Assumptions!$B$27 | C5: €
A6: Gross Profit per can | B6: =B5-B6 | C6: €
A7: Gross Margin % | B7: =B7/B5 | C7: %
C8: FALSE
A9: Variable Marketing Cost per can | B9: =Assumptions!$B$66*B5 | C9: €
A10: Contribution Margin I | B10: =B7-B10 | C10: €
A11: CM I % | B11: =B11/B5 | C11: %
C12: FALSE
A13: CUSTOMER ACQUISITION COST (CAC) | C13: TRUE
A14: Average Marketing Spend (Y1) | B14: ='P&L Year 1 (Monthly)'!N26 | C14: €
A15: New Customers Acquired (Y1) | B15: =Assumptions!$B$38*0.7 | C15: customers
A16: CAC | B16: =B15/B16 | C16: € per customer
C17: FALSE
A18: LIFETIME VALUE (LTV) | C18: TRUE
A19: Average Purchase Frequency | B19: 24 | C19: cans/year
A20: Average Customer Lifetime | B20: 3 | C20: years
A21: Total Lifetime Purchases | B21: =B21*B22 | C21: cans
A22: CM I per customer (lifetime) | B22: =B23*B11 | C22: €
A23: LTV | B23: =B24 | C23: €
C24: FALSE
A25: LTV / CAC RATIO | B25: =B25/B17 | C25: ratio
A26: Target Ratio | B26: >3.0 | C26: benchmark
C27: FALSE
A28: BREAK-EVEN VOLUME (per can) | C28: TRUE
A29: Fixed Costs (Y1 annual) | B29: ='P&L Year 1 (Monthly)'!N31-'P&L Year 1 (Monthly)'!N26 | C29: €
A30: CM I per can | B30: =B11 | C30: €
A31: Break-even Volume | B31: =B32/B33 | C31: cans
A32: Break-even as % of Y1 plan | B32: =B34/Assumptions!$B$38 | C32: %

Sheet Base Case
A1: DEEP DIVE BOTANICALS - BASE CASE
A3: Scenario Adjustments:
A4: Volume: +0%
A5: COGS: €+0.00
A6: Margin: +0.0%
A8: Metric | B8: Year 1 | C8: Year 2 | D8: Year 3 | E8: 3-Year Total
A9: Volume (cans) | B9: =Assumptions!$B$38*(1+0.0) | C9: =Assumptions!$B$39*(1+0.0) | D9: =Assumptions!$B$40*(1+0.0) | E9: =SUM(B9:D9)
A10: Revenue | B10: =B10*Assumptions!$B$12 | C10: =B10*Assumptions!$B$12 | D10: =B10*Assumptions!$B$12 | E10: =SUM(B10:D10)
A11: COGS | B11: =B11*(Assumptions!$B$27+0.0) | C11: =B11*(Assumptions!$B$27+0.0) | D11: =B11*(Assumptions!$B$27+0.0) | E11: =SUM(B11:D11)
A12: Gross Profit | B12: =B10-B11 | C12: =B10-B11 | D12: =B10-B11 | E12: =SUM(B12:D12)
A13: Gross Margin % | B13: =B12/B10 | C13: =B12/B10 | D13: =B12/B10 | E13: =AVERAGE(B13:D13)
A14: Operating Expenses | B14: =B10*0.25 | C14: =B10*0.25 | D14: =B10*0.25 | E14: =SUM(B14:D14)
A15: EBITDA | B15: =B12-B14 | C15: =B12-B14 | D15: =B12-B14 | E15: =SUM(B15:D15)
A16: EBITDA Margin % | B16: =B15/B10 | C16: =B15/B10 | D16: =B15/B10 | E16: =AVERAGE(B16:D16)
A17: Net Income | B17: =B15*0.7 | C17: =B15*0.7 | D17: =B15*0.7 | E17: =SUM(B17:D17)
A18: Net Margin % | B18: =B17/B10 | C18: =B17/B10 | D18: =B17/B10 | E18: =AVERAGE(B18:D18)
A19: Cumulative Cash Position | B19: =Assumptions!$B$81+Assumptions!$B$82+B18 | C19: =B19+B18 | D19: =C19+B18 | E19: =D19

Sheet Bull Case
A1: DEEP DIVE BOTANICALS - BULL CASE
A3: Scenario Adjustments:
A4: Volume: +20%
A5: COGS: €-0.03
A6: Margin: +2.0%
A8: Metric | B8: Year 1 | C8: Year 2 | D8: Year 3 | E8: 3-Year Total
A9: Volume (cans) | B9: =Assumptions!$B$38*(1+0.2) | C9: =Assumptions!$B$39*(1+0.2) | D9: =Assumptions!$B$40*(1+0.2) | E9: =SUM(B9:D9)
A10: Revenue | B10: =B10*Assumptions!$B$12 | C10: =B10*Assumptions!$B$12 | D10: =B10*Assumptions!$B$12 | E10: =SUM(B10:D10)
A11: COGS | B11: =B11*(Assumptions!$B$27+-0.03) | C11: =B11*(Assumptions!$B$27+-0.03) | D11: =B11*(Assumptions!$B$27+-0.03) | E11: =SUM(B11:D11)
A12: Gross Profit | B12: =B10-B11 | C12: =B10-B11 | D12: =B10-B11 | E12: =SUM(B12:D12)
A13: Gross Margin % | B13: =B12/B10 | C13: =B12/B10 | D13: =B12/B10 | E13: =AVERAGE(B13:D13)
A14: Operating Expenses | B14: =B10*0.25 | C14: =B10*0.25 | D14: =B10*0.25 | E14: =SUM(B14:D14)
A15: EBITDA | B15: =B12-B14 | C15: =B12-B14 | D15: =B12-B14 | E15: =SUM(B15:D15)
A16: EBITDA Margin % | B16: =B15/B10 | C16: =B15/B10 | D16: =B15/B10 | E16: =AVERAGE(B16:D16)
A17: Net Income | B17: =B15*0.7 | C17: =B15*0.7 | D17: =B15*0.7 | E17: =SUM(B17:D17)
A18: Net Margin % | B18: =B17/B10 | C18: =B17/B10 | D18: =B17/B10 | E18: =AVERAGE(B18:D18)
A19: Cumulative Cash Position | B19: =Assumptions!$B$81+Assumptions!$B$82+B18 | C19: =B19+B18 | D19: =C19+B18 | E19: =D19

Sheet Bear Case
A1: DEEP DIVE BOTANICALS - BEAR CASE
A3: Scenario Adjustments:
A4: Volume: -20%
A5: COGS: €+0.03
A6: Margin: -2.0%
A8: Metric | B8: Year 1 | C8: Year 2 | D8: Year 3 | E8: 3-Year Total
A9: Volume (cans) | B9: =Assumptions!$B$38*(1+-0.2) | C9: =Assumptions!$B$39*(1+-0.2) | D9: =Assumptions!$B$40*(1+-0.2) | E9: =SUM(B9:D9)
A10: Revenue | B10: =B10*Assumptions!$B$12 | C10: =B10*Assumptions!$B$12 | D10: =B10*Assumptions!$B$12 | E10: =SUM(B10:D10)
A11: COGS | B11: =B11*(Assumptions!$B$27+0.03) | C11: =B11*(Assumptions!$B$27+0.03) | D11: =B11*(Assumptions!$B$27+0.03) | E11: =SUM(B11:D11)
A12: Gross Profit | B12: =B10-B11 | C12: =B10-B11 | D12: =B10-B11 | E12: =SUM(B12:D12)
A13: Gross Margin % | B13: =B12/B10 | C13: =B12/B10 | D13: =B12/B10 | E13: =AVERAGE(B13:D13)
A14: Operating Expenses | B14: =B10*0.25 | C14: =B10*0.25 | D14: =B10*0.25 | E14: =SUM(B14:D14)
A15: EBITDA | B15: =B12-B14 | C15: =B12-B14 | D15: =B12-B14 | E15: =SUM(B15:D15)
A16: EBITDA Margin % | B16: =B15/B10 | C16: =B15/B10 | D16: =B15/B10 | E16: =AVERAGE(B16:D16)
A17: Net Income | B17: =B15*0.7 | C17: =B15*0.7 | D17: =B15*0.7 | E17: =SUM(B17:D17)
A18: Net Margin % | B18: =B17/B10 | C18: =B17/B10 | D18: =B17/B10 | E18: =AVERAGE(B18:D18)
A19: Cumulative Cash Position | B19: =Assumptions!$B$81+Assumptions!$B$82+B18 | C19: =B19+B18 | D19: =C19+B18 | E19: =D19

Sheet Sensitivity Analysis
A1: DEEP DIVE BOTANICALS - SENSITIVITY ANALYSIS
A4: 1. COGS Impact on Gross Margin % (Year 1)
A5: COGS Change | B5: Gross Margin %
A6: -0.05 | B6: =(Assumptions!$B$12-(Assumptions!$B$27+-0.05))/Assumptions!$B$12
A7: -0.03 | B7: =(Assumptions!$B$12-(Assumptions!$B$27+-0.03))/Assumptions!$B$12
A8: -0.01 | B8: =(Assumptions!$B$12-(Assumptions!$B$27+-0.01))/Assumptions!$B$12
A9: 0 | B9: =(Assumptions!$B$12-(Assumptions!$B$27+0.0))/Assumptions!$B$12
A10: 0.01 | B10: =(Assumptions!$B$12-(Assumptions!$B$27+0.01))/Assumptions!$B$12
A11: 0.03 | B11: =(Assumptions!$B$12-(Assumptions!$B$27+0.03))/Assumptions!$B$12
A12: 0.05 | B12: =(Assumptions!$B$12-(Assumptions!$B$27+0.05))/Assumptions!$B$12
A15: 2. Volume Impact on Year 1 Ending Cash
A16: Volume Change | B16: Ending Cash (€)
A17: -0.2 | B17: ='Cash Flow Statement'!N25*(1+-0.4)
A18: -0.1 | B18: ='Cash Flow Statement'!N25*(1+-0.2)
A19: -0.05 | B19: ='Cash Flow Statement'!N25*(1+-0.1)
A20: 0 | B20: ='Cash Flow Statement'!N25*(1+0.0)
A21: 0.05 | B21: ='Cash Flow Statement'!N25*(1+0.1)
A22: 0.1 | B22: ='Cash Flow Statement'!N25*(1+0.2)
A23: 0.2 | B23: ='Cash Flow Statement'!N25*(1+0.4)
A26: 3. Price vs Volume Impact on Year 1 Revenue
A27: Price \ Volume | B27: -0.2 | C27: -0.1 | D27: 0 | E27: 0.1 | F27: 0.2
A28: -0.05 | B28: =Assumptions!$B$38*(1+-0.2)*(Assumptions!$B$12+-0.05) | C28: =Assumptions!$B$38*(1+-0.1)*(Assumptions!$B$12+-0.05) | D28: =Assumptions!$B$38*(1+0.0)*(Assumptions!$B$12+-0.05) | E28: =Assumptions!$B$38*(1+0.1)*(Assumptions!$B$12+-0.05) | F28: =Assumptions!$B$38*(1+0.2)*(Assumptions!$B$12+-0.05)
A29: -0.02 | B29: =Assumptions!$B$38*(1+-0.2)*(Assumptions!$B$12+-0.02) | C29: =Assumptions!$B$38*(1+-0.1)*(Assumptions!$B$12+-0.02) | D29: =Assumptions!$B$38*(1+0.0)*(Assumptions!$B$12+-0.02) | E29: =Assumptions!$B$38*(1+0.1)*(Assumptions!$B$12+-0.02) | F29: =Assumptions!$B$38*(1+0.2)*(Assumptions!$B$12+-0.02)
A30: 0 | B30: =Assumptions!$B$38*(1+-0.2)*(Assumptions!$B$12+0.0) | C30: =Assumptions!$B$38*(1+-0.1)*(Assumptions!$B$12+0.0) | D30: =Assumptions!$B$38*(1+0.0)*(Assumptions!$B$12+0.0) | E30: =Assumptions!$B$38*(1+0.1)*(Assumptions!$B$12+0.0) | F30: =Assumptions!$B$38*(1+0.2)*(Assumptions!$B$12+0.0)
A31: 0.02 | B31: =Assumptions!$B$38*(1+-0.2)*(Assumptions!$B$12+0.02) | C31: =Assumptions!$B$38*(1+-0.1)*(Assumptions!$B$12+0.02) | D31: =Assumptions!$B$38*(1+0.0)*(Assumptions!$B$12+0.02) | E31: =Assumptions!$B$38*(1+0.1)*(Assumptions!$B$12+0.02) | F31: =Assumptions!$B$38*(1+0.2)*(Assumptions!$B$12+0.02)
A32: 0.05 | B32: =Assumptions!$B$38*(1+-0.2)*(Assumptions!$B$12+0.05) | C32: =Assumptions!$B$38*(1+-0.1)*(Assumptions!$B$12+0.05) | D32: =Assumptions!$B$38*(1+0.0)*(Assumptions!$B$12+0.05) | E32: =Assumptions!$B$38*(1+0.1)*(Assumptions!$B$12+0.05) | F32: =Assumptions!$B$38*(1+0.2)*(Assumptions!$B$12+0.05)

Sheet Break-Even Analysis
A1: DEEP DIVE BOTANICALS - BREAK-EVEN ANALYSIS
A3: FIXED COSTS (Annual) | C3: TRUE
A4: Personnel (incl. contributions) | B4: =(Assumptions!$B$59+Assumptions!$B$60+Assumptions!$B$61)*(1+Assumptions!$B$62) | C4: €
A5: G&A | B5: =Assumptions!$B$67*12 | C5: €
A6: Quality/Lab | B6: =Assumptions!$B$68 | C6: €
A7: Design (one-time) | B7: =Assumptions!$B$69 | C7: €
A8: Insurance | B8: =Assumptions!$B$70 | C8: €
A9: Legal/Accounting | B9: =Assumptions!$B$71 | C9: €
A10: Total Fixed Costs | B10: =SUM(B5:B10) | C10: €
C11: FALSE
A12: VARIABLE COSTS (per unit) | C12: TRUE
A13: COGS per can | B13: =Assumptions!$B$27 | C13: €
A14: Variable Marketing (% of revenue) | B14: =Assumptions!$B$66 | C14: %
C15: FALSE
A16: PRICING | C16: TRUE
A17: Selling Price (ex-factory) | B17: =Assumptions!$B$12 | C17: €
C18: FALSE
A19: CONTRIBUTION MARGIN | C19: TRUE
A20: Price per unit | B20: =B18 | C20: €
A21: Variable Cost per unit | B21: =B14 | C21: €
A22: Contribution Margin per unit | B22: =B21-B22 | C22: €
A23: CM % | B23: =B23/B21 | C23: %
C24: FALSE
A25: BREAK-EVEN CALCULATION | C25: TRUE
A26: Break-Even Units | B26: =B11/B23 | C26: cans
A27: Break-Even Revenue | B27: =B27*B18 | C27: €
C28: FALSE
A29: VS. YEAR 1 PLAN | C29: TRUE
A30: Planned Volume Y1 | B30: =Assumptions!$B$38 | C30: cans
A31: Break-Even as % of Plan | B31: =B27/B31 | C31: %
A32: Units Above Break-Even | B32: =B31-B27 | C32: cans
A33: Margin of Safety | B33: =B33/B31 | C33: %
C34: FALSE
A35: BREAK-EVEN TIMING | C35: TRUE
A36: Monthly Average Sales | B36: =B31/12 | C36: cans/month
A37: Months to Break-Even | B37: =B27/B37 | C37: months
A38: Expected Break-Even Month | B38: =ROUNDUP(B38,0) | C38: month

Sheet Use of Funds
A1: DEEP DIVE BOTANICALS - USE OF FUNDS (€500K PRE-SEED)
A3: Category | B3: Amount (€) | C3: % of Total | D3: Description
A4: Production & Inventory | B4: 200000 | C4: 0.4 | D4: Can inventory (MOQ), ingredients, co-packing for first 150k units
A5: Marketing & Sales | B5: 75000 | C5: 0.15 | D5: Launch campaign, trade shows, sampling, promotional materials, POS
A6: Personnel (18 months) | B6: 135000 | C6: 0.27 | D6: Founder salary (post-funding), ops & sales assistants
A7: Working Capital | B7: 50000 | C7: 0.1 | D7: AR/AP financing, payment terms bridge
A8: Quality & Regulatory | B8: 15000 | C8: 0.03 | D8: Lab testing, certifications, compliance
A9: Design & Branding | B9: 10000 | C9: 0.02 | D9: Label design, website, brand materials
A10: Legal & Admin | B10: 10000 | C10: 0.02 | D10: Company setup, contracts, IP protection, accounting
A11: Reserve/Contingency | B11: 5000 | C11: 0.01 | D11: 1% buffer for unexpected costs
A12: TOTAL FUNDING | B12: =SUM(B4:B11) | C12: =SUM(C4:C11)
A15: MILESTONE-BASED FUNDING TRANCHES
A16: Tranche | B16: Amount (€) | C16: Milestone | D16: Timeline
A17: Tranche 1 | B17: 250000 | C17: Initial funding at closing | D17: Month 0
A18: Tranche 2 | B18: 150000 | C18: After pilot batch sold (20k units) | D18: Month 3-4
A19: Tranche 3 | B19: 100000 | C19: After 50k total units sold + 3 retail partners | D19: Month 6-8
